<?xml version="1.0"?>
<robot name="razbot2_arm" xmlns:xacro="http://ros.org/wiki/xacro">

  <xacro:macro name="razbot2_arm" params="prefix *origin">

    <!-- Arm base link and joint to link_0 -->
    <link name="${prefix}razbot2_arm_base_link">
      <visual>
        <origin xyz="0 0 0" rpy="0 0 0 "/>
        <geometry>
          <mesh filename="package://razbot2_description/meshes/razbot2_arm/razbot2_arm_base_link.stl" />
        </geometry>
        <material name="Grey" />
      </visual>
      <collision>
        <origin xyz="0 0 0" rpy="0 0 0" />
        <geometry>
          <mesh filename="package://razbot2_description/meshes/razbot2_arm/razbot2_arm_base_link.stl" />
        </geometry>
      </collision>
      <inertial>
        <origin xyz="0 0.1 0"/>
        <mass value="0.15" />
        <inertia  ixx="0.0001" ixy="0" ixz="0"
                  iyy="0.0001" iyz="0"
                  izz="0.0001" />
      </inertial>
    </link>
    <gazebo reference="${prefix}razbot2_arm_base_link">
      <mu1 value="200.0"/>
      <mu2 value="100.0"/>
      <kp value="10000000.0" />
      <kd value="1.0" />
      <material>Gazebo/Grey</material>
    </gazebo>
    <joint name="${prefix}razbot2_arm_base_link_to_0_joint" type="revolute">
      <parent link="${prefix}razbot2_arm_base_link"/>
      <child link="${prefix}razbot2_arm_link_0"/>
      <axis xyz="0 0 0" rpy="0 0 0" />
    </joint>

  </xacro:macro>
</robot>
